[2022-11-04 00:15:42,682] {taskinstance.py:1159} INFO - Dependencies all met for <TaskInstance: user_processing.is_api_available scheduled__2022-11-03T00:00:00+00:00 [queued]>
[2022-11-04 00:15:42,698] {taskinstance.py:1159} INFO - Dependencies all met for <TaskInstance: user_processing.is_api_available scheduled__2022-11-03T00:00:00+00:00 [queued]>
[2022-11-04 00:15:42,701] {taskinstance.py:1356} INFO - 
--------------------------------------------------------------------------------
[2022-11-04 00:15:42,710] {taskinstance.py:1357} INFO - Starting attempt 1 of 1
[2022-11-04 00:15:42,717] {taskinstance.py:1358} INFO - 
--------------------------------------------------------------------------------
[2022-11-04 00:15:42,767] {taskinstance.py:1377} INFO - Executing <Task(HttpSensor): is_api_available> on 2022-11-03 00:00:00+00:00
[2022-11-04 00:15:42,794] {standard_task_runner.py:52} INFO - Started process 71561 to run task
[2022-11-04 00:15:42,808] {standard_task_runner.py:79} INFO - Running: ['***', 'tasks', 'run', 'user_processing', 'is_api_available', 'scheduled__2022-11-03T00:00:00+00:00', '--job-id', '19', '--raw', '--subdir', 'DAGS_FOLDER/user_processing.py', '--cfg-path', '/tmp/tmp01den63i', '--error-file', '/tmp/tmp28cbrtmu']
[2022-11-04 00:15:42,825] {standard_task_runner.py:80} INFO - Job 19: Subtask is_api_available
[2022-11-04 00:15:42,954] {task_command.py:369} INFO - Running <TaskInstance: user_processing.is_api_available scheduled__2022-11-03T00:00:00+00:00 [running]> on host 601dc51f5629
[2022-11-04 00:15:43,035] {taskinstance.py:1571} INFO - Exporting the following env vars:
AIRFLOW_CTX_DAG_OWNER=***
AIRFLOW_CTX_DAG_ID=user_processing
AIRFLOW_CTX_TASK_ID=is_api_available
AIRFLOW_CTX_EXECUTION_DATE=2022-11-03T00:00:00+00:00
AIRFLOW_CTX_TRY_NUMBER=1
AIRFLOW_CTX_DAG_RUN_ID=scheduled__2022-11-03T00:00:00+00:00
[2022-11-04 00:15:43,038] {http.py:97} INFO - Poking: api/
[2022-11-04 00:15:43,056] {base.py:68} INFO - Using connection ID 'user_api' for task execution.
[2022-11-04 00:15:43,071] {http.py:129} INFO - Sending 'GET' to url: https://randomuser.me/api/
[2022-11-04 00:15:43,100] {http.py:187} WARNING - HTTPSConnectionPool(host='randomuser.me', port=443): Max retries exceeded with url: /api/ (Caused by NewConnectionError('<urllib3.connection.HTTPSConnection object at 0xffff86dd2bd0>: Failed to establish a new connection: [Errno -2] Name or service not known')) Tenacity will retry to execute the operation
[2022-11-04 00:15:43,101] {taskinstance.py:1889} ERROR - Task failed with exception
Traceback (most recent call last):
  File "/home/airflow/.local/lib/python3.7/site-packages/urllib3/connection.py", line 175, in _new_conn
    (self._dns_host, self.port), self.timeout, **extra_kw
  File "/home/airflow/.local/lib/python3.7/site-packages/urllib3/util/connection.py", line 72, in create_connection
    for res in socket.getaddrinfo(host, port, family, socket.SOCK_STREAM):
  File "/usr/local/lib/python3.7/socket.py", line 752, in getaddrinfo
    for res in _socket.getaddrinfo(host, port, family, type, proto, flags):
socket.gaierror: [Errno -2] Name or service not known

During handling of the above exception, another exception occurred:

Traceback (most recent call last):
  File "/home/airflow/.local/lib/python3.7/site-packages/urllib3/connectionpool.py", line 710, in urlopen
    chunked=chunked,
  File "/home/airflow/.local/lib/python3.7/site-packages/urllib3/connectionpool.py", line 386, in _make_request
    self._validate_conn(conn)
  File "/home/airflow/.local/lib/python3.7/site-packages/urllib3/connectionpool.py", line 1040, in _validate_conn
    conn.connect()
  File "/home/airflow/.local/lib/python3.7/site-packages/urllib3/connection.py", line 358, in connect
    self.sock = conn = self._new_conn()
  File "/home/airflow/.local/lib/python3.7/site-packages/urllib3/connection.py", line 187, in _new_conn
    self, "Failed to establish a new connection: %s" % e
urllib3.exceptions.NewConnectionError: <urllib3.connection.HTTPSConnection object at 0xffff86dd2bd0>: Failed to establish a new connection: [Errno -2] Name or service not known

During handling of the above exception, another exception occurred:

Traceback (most recent call last):
  File "/home/airflow/.local/lib/python3.7/site-packages/requests/adapters.py", line 450, in send
    timeout=timeout
  File "/home/airflow/.local/lib/python3.7/site-packages/urllib3/connectionpool.py", line 786, in urlopen
    method, url, error=e, _pool=self, _stacktrace=sys.exc_info()[2]
  File "/home/airflow/.local/lib/python3.7/site-packages/urllib3/util/retry.py", line 592, in increment
    raise MaxRetryError(_pool, url, error or ResponseError(cause))
urllib3.exceptions.MaxRetryError: HTTPSConnectionPool(host='randomuser.me', port=443): Max retries exceeded with url: /api/ (Caused by NewConnectionError('<urllib3.connection.HTTPSConnection object at 0xffff86dd2bd0>: Failed to establish a new connection: [Errno -2] Name or service not known'))

During handling of the above exception, another exception occurred:

Traceback (most recent call last):
  File "/home/airflow/.local/lib/python3.7/site-packages/airflow/sensors/base.py", line 277, in execute
    poke_return = self.poke(context)
  File "/home/airflow/.local/lib/python3.7/site-packages/airflow/providers/http/sensors/http.py", line 103, in poke
    extra_options=self.extra_options,
  File "/home/airflow/.local/lib/python3.7/site-packages/airflow/providers/http/hooks/http.py", line 130, in run
    return self.run_and_check(session, prepped_request, extra_options)
  File "/home/airflow/.local/lib/python3.7/site-packages/airflow/providers/http/hooks/http.py", line 188, in run_and_check
    raise ex
  File "/home/airflow/.local/lib/python3.7/site-packages/airflow/providers/http/hooks/http.py", line 180, in run_and_check
    response = session.send(prepped_request, **send_kwargs)
  File "/home/airflow/.local/lib/python3.7/site-packages/requests/sessions.py", line 645, in send
    r = adapter.send(request, **kwargs)
  File "/home/airflow/.local/lib/python3.7/site-packages/requests/adapters.py", line 519, in send
    raise ConnectionError(e, request=request)
requests.exceptions.ConnectionError: HTTPSConnectionPool(host='randomuser.me', port=443): Max retries exceeded with url: /api/ (Caused by NewConnectionError('<urllib3.connection.HTTPSConnection object at 0xffff86dd2bd0>: Failed to establish a new connection: [Errno -2] Name or service not known'))
[2022-11-04 00:15:43,121] {taskinstance.py:1400} INFO - Marking task as FAILED. dag_id=user_processing, task_id=is_api_available, execution_date=20221103T000000, start_date=20221104T001542, end_date=20221104T001543
[2022-11-04 00:15:43,159] {standard_task_runner.py:97} ERROR - Failed to execute job 19 for task is_api_available (HTTPSConnectionPool(host='randomuser.me', port=443): Max retries exceeded with url: /api/ (Caused by NewConnectionError('<urllib3.connection.HTTPSConnection object at 0xffff86dd2bd0>: Failed to establish a new connection: [Errno -2] Name or service not known')); 71561)
[2022-11-04 00:15:43,240] {local_task_job.py:156} INFO - Task exited with return code 1
[2022-11-04 00:15:43,313] {local_task_job.py:273} INFO - 0 downstream tasks scheduled from follow-on schedule check
