[2022-10-31 19:14:37,536] {taskinstance.py:1159} INFO - Dependencies all met for <TaskInstance: user_processing.process_user scheduled__2022-10-30T00:00:00+00:00 [queued]>
[2022-10-31 19:14:37,559] {taskinstance.py:1159} INFO - Dependencies all met for <TaskInstance: user_processing.process_user scheduled__2022-10-30T00:00:00+00:00 [queued]>
[2022-10-31 19:14:37,560] {taskinstance.py:1356} INFO - 
--------------------------------------------------------------------------------
[2022-10-31 19:14:37,561] {taskinstance.py:1357} INFO - Starting attempt 1 of 1
[2022-10-31 19:14:37,563] {taskinstance.py:1358} INFO - 
--------------------------------------------------------------------------------
[2022-10-31 19:14:37,605] {taskinstance.py:1377} INFO - Executing <Task(PythonOperator): process_user> on 2022-10-30 00:00:00+00:00
[2022-10-31 19:14:37,618] {standard_task_runner.py:52} INFO - Started process 13123 to run task
[2022-10-31 19:14:37,626] {standard_task_runner.py:79} INFO - Running: ['***', 'tasks', 'run', 'user_processing', 'process_user', 'scheduled__2022-10-30T00:00:00+00:00', '--job-id', '9', '--raw', '--subdir', 'DAGS_FOLDER/user_processing.py', '--cfg-path', '/tmp/tmplsi3t6ie', '--error-file', '/tmp/tmpuwxm4c_j']
[2022-10-31 19:14:37,627] {standard_task_runner.py:80} INFO - Job 9: Subtask process_user
[2022-10-31 19:14:37,939] {task_command.py:369} INFO - Running <TaskInstance: user_processing.process_user scheduled__2022-10-30T00:00:00+00:00 [running]> on host 601dc51f5629
[2022-10-31 19:14:38,213] {taskinstance.py:1571} INFO - Exporting the following env vars:
AIRFLOW_CTX_DAG_OWNER=***
AIRFLOW_CTX_DAG_ID=user_processing
AIRFLOW_CTX_TASK_ID=process_user
AIRFLOW_CTX_EXECUTION_DATE=2022-10-30T00:00:00+00:00
AIRFLOW_CTX_TRY_NUMBER=1
AIRFLOW_CTX_DAG_RUN_ID=scheduled__2022-10-30T00:00:00+00:00
[2022-10-31 19:14:38,256] {taskinstance.py:1889} ERROR - Task failed with exception
Traceback (most recent call last):
  File "/home/airflow/.local/lib/python3.7/site-packages/airflow/operators/python.py", line 171, in execute
    return_value = self.execute_callable()
  File "/home/airflow/.local/lib/python3.7/site-packages/airflow/operators/python.py", line 189, in execute_callable
    return self.python_callable(*self.op_args, **self.op_kwargs)
  File "/opt/airflow/dags/user_processing.py", line 14, in _process_user
    user = user["results"][0]
TypeError: 'NoneType' object is not subscriptable
[2022-10-31 19:14:38,295] {taskinstance.py:1400} INFO - Marking task as FAILED. dag_id=user_processing, task_id=process_user, execution_date=20221030T000000, start_date=20221031T191437, end_date=20221031T191438
[2022-10-31 19:14:38,373] {standard_task_runner.py:97} ERROR - Failed to execute job 9 for task process_user ('NoneType' object is not subscriptable; 13123)
[2022-10-31 19:14:38,462] {local_task_job.py:156} INFO - Task exited with return code 1
[2022-10-31 19:14:38,538] {local_task_job.py:273} INFO - 0 downstream tasks scheduled from follow-on schedule check
